<?xml version="1.0" ?>




<sdf version="1.5">
  <model name="Double_Inverted_Pendulum">
    <pose>0.0 0.0 0.0 0.0 0.0 0.0</pose>
    <static>false</static>
    <self_collide>false</self_collide>

    <link name="base_link">
    <pose>0.0 0.0 1.375 0.0 0.0 0.0</pose>
    <inertial>
      <pose>0 0 -1.375 0 0 0</pose>
      <inertia>
        <ixx>0.1</ixx>
        <ixy>0.0</ixy>
        <ixz>0.0</ixz>
        <iyy>0.1</iyy>
        <iyz>0.0</iyz>
        <izz>0.1</izz>
      </inertia>
      <mass>0.1</mass>
    </inertial>
    <visual name="base_visual">
      <pose>0.0 0.0 -0.05 0.0 1.57079632679 0.0</pose>
      <geometry>
        <cylinder>
          <radius>0.025</radius>
          <length>10.0</length>
        </cylinder>
      </geometry>
    </visual>
    </link>

    <joint name="fixed_to_ground" type="fixed">
      <parent>world</parent>
      <child>base_link</child>
    </joint>

    <link name="cart_link">
    <pose>0.0 0.0 1.375 0.0 0.0 0.0</pose>
    <inertial>
      <pose>0.0 0.0 0.0 0.0 0.0 0.0</pose>
      <inertia>
        <ixx>0.005625000000000001</ixx>
        <ixy>0</ixy>
        <ixz>0</ixz>
        <iyy>0.0078125</iyy>
        <iyz>0</iyz>
        <izz>0.0078125</izz>
      </inertia>
      <mass>1.5</mass>
    </inertial>
      <visual name="cart_visual">
        <pose>0.0 0.0 -0.075 0.0 0.0 0.0</pose>
        <geometry>
          <box>
            <size>0.2 0.15 0.15</size>
          </box>
        </geometry>
      </visual>
    </link>

    <joint name="cart_joint" type="prismatic">
      <parent>base_link</parent>
      <child>cart_link</child>
      <axis>
        <xyz>1 0 0</xyz>
        <limit>
          <lower>-10</lower>
          <upper>10</upper>
        </limit>
      </axis>
    </joint>

    <link name="firstpendulum_link">
    <pose>0 0 1.375 0 0 0</pose>
    <inertial>
      <pose>0 0 0.25 0 0 0</pose>
      <inertia>
        <ixx>0.010416666666666666</ixx>
        <ixy>0</ixy>
        <ixz>0</ixz>
        <iyy>0.010416666666666666</iyy>
        <iyz>0</iyz>
        <izz>0.00015625000000000003</izz>
      </inertia>
      <mass>0.5</mass>
    </inertial>
      <visual name="firstpendulum_visual">
        <pose>0 0 0.25 0 0 0</pose>
        <geometry>
          <cylinder>
            <radius>0.025</radius>
            <length>0.5</length>
          </cylinder>
        </geometry>
        <material>
          <script>
            <uri>file://media/materials/scripts/gazebo.material</uri>
            <name>Gazebo/Blue</name>
          </script>
        </material>
      </visual>
    </link>

    <joint name="firstpendulum_joint" type="revolute">
    <parent>cart_link</parent>
    <child>firstpendulum_link</child>
    <axis>
      <xyz>0 1 0</xyz>
      <dynamics>
        <damping>0.005</damping>
      </dynamics>
    </axis>
    </joint>

    <link name="secondpendulum_link">
    <pose>0 0 1.875 0 0 0</pose>
    <inertial>
      <pose>0 0 0.375 0 0 0</pose>
      <inertia>
        <ixx>0.03515625</ixx>
        <ixy>0</ixy>
        <ixz>0</ixz>
        <iyy>0.03515625</iyy>
        <iyz>0</iyz>
        <izz>0.00015625000000000003</izz>
      </inertia>
      <mass>0.75</mass>
    </inertial>
      <visual name="secondpendulum_visual">
        <pose>0 0 0.375 0 0 0</pose>
        <geometry>
          <cylinder>
            <radius>0.025</radius>
            <length>0.75</length>
          </cylinder>
        </geometry>
        <material>
          <script>
            <uri>file://media/materials/scripts/gazebo.material</uri>
            <name>Gazebo/Red</name>
          </script>
        </material>
      </visual>
    </link>

    <joint name="secondpendulum_joint" type="revolute">
    <parent>firstpendulum_link</parent>
    <child>secondpendulum_link</child>
    <axis>
      <xyz>0 1 0</xyz>
      <dynamics>
        <damping>0.005</damping>
      </dynamics>
    </axis>
    </joint>


    <plugin name="pendulum_stabilization" filename="libpendulum_stabilization.so">
    <cart_joint>cart_joint</cart_joint>
    <first_pendulum_joint>firstpendulum_joint</first_pendulum_joint>
    <second_pendulum_joint>secondpendulum_joint</second_pendulum_joint>
    </plugin>


  </model>
</sdf>
