<?xml version="1.0" ?>

<%
# ----------------
#  Parameters
# ----------------

# Visual
R  = 0.025 # rod radius (m)

# Cart
m0   = 1.5 # Mass (kg)

# Pendulum 1
m1  = 0.5 # Mass (kg)
L1  = 0.5 # Length (m)
a1  = 0.25 # CoG (m)
J1  = m1 * L1 * L1 / 12 # Moment of inertia (N m s²)
d1  = 0.005 # Friction constant (N m s)

# Pendulum 2
m2  = 0.75 # Mass (kg)
L2  = 0.75 # Length (m)
a2  = 0.375 # CoG (m)
J2  = m2 * L2 * L2 / 12 # Moment of inertia (N m s²)
d2  = 0.005 # Friction constant (N m s)

# Misc
height = 1.1 * (L1 + L2)
%>


<sdf version="1.5">
  <model name="Double_Inverted_Pendulum">
    <pose>0.0 0.0 0.0 0.0 0.0 0.0</pose>
    <static>false</static>
    <self_collide>false</self_collide>

    <link name="base_link">
    <pose>0.0 0.0 <%= height %> 0.0 0.0 0.0</pose>
    <inertial>
      <pose>0 0 <%= -height %> 0 0 0</pose>
      <inertia>
        <ixx>0.1</ixx>
        <ixy>0.0</ixy>
        <ixz>0.0</ixz>
        <iyy>0.1</iyy>
        <iyz>0.0</iyz>
        <izz>0.1</izz>
      </inertia>
      <mass><%= 0.1 %></mass>
    </inertial>
    <visual name="base_visual">
      <pose>0.0 0.0 -0.05 0.0 1.57079632679 0.0</pose>
      <geometry>
        <cylinder>
          <radius><%= R %></radius>
          <length>10.0</length>
        </cylinder>
      </geometry>
    </visual>
    </link>

    <joint name="fixed_to_ground" type="fixed">
    <parent>world</parent>
    <child>base_link</child>
    </joint>

    <link name="cart_link">
    <pose>0.0 0.0 <%= height %> 0.0 0.0 0.0</pose>
    <inertial>
      <pose>0.0 0.0 0.0 0.0 0.0 0.0</pose>
      <inertia>
        <ixx><%= m0*(0.15*0.15 + 0.15*0.15)/12 %></ixx>
        <ixy>0</ixy>
        <ixz>0</ixz>
        <iyy><%= m0*(0.2*0.2 + 0.15*0.15)/12 %></iyy>
        <iyz>0</iyz>
        <izz><%= m0*(0.2*0.2 + 0.15*0.15)/12 %></izz>
      </inertia>
      <mass><%= m0 %></mass>
    </inertial>
      <visual name="cart_visual">
        <pose>0.0 0.0 -0.075 0.0 0.0 0.0</pose>
        <geometry>
          <box>
            <size>0.2 0.15 0.15</size>
          </box>
        </geometry>
      </visual>
    </link>

    <joint name="cart_joint" type="prismatic">
    <parent>base_link</parent>
    <child>cart_link</child>
    </joint>

    <link name="firstpendulum_link">
    <pose>0 0 <%= height %> 0 0 0</pose>
    <inertial>
      <pose>0 0 <%= a1 %> 0 0 0</pose>
      <inertia>
        <ixx><%= J1 %></ixx>
        <ixy>0</ixy>
        <ixz>0</ixz>
        <iyy><%= J1 %></iyy>
        <iyz>0</iyz>
        <izz><%= 0.5*m1*R*R %></izz>
      </inertia>
      <mass><%= m1 %></mass>
    </inertial>
      <visual name="firstpendulum_visual">
        <pose>0 0 <%= (L1/2.0) %> 0 0 0</pose>
        <geometry>
          <cylinder>
            <radius><%= R %></radius>
            <length><%= L1 %></length>
          </cylinder>
        </geometry>
        <material>
          <script>
            <uri>file://media/materials/scripts/gazebo.material</uri>
            <name>Gazebo/Blue</name>
          </script>
        </material>
      </visual>
    </link>

    <joint name="firstpendulum_joint" type="revolute">
    <parent>cart_link</parent>
    <child>firstpendulum_link</child>
    <axis>
      <xyz>0 1 0</xyz>
      <dynamics>
        <damping><%= d1 %></damping>
      </dynamics>
    </axis>
    </joint>

    <link name="secondpendulum_link">
    <pose>0 0 <%= height + L1 %> 0 0 0</pose>
    <inertial>
      <pose>0 0 <%= a2 %> 0 0 0</pose>
      <inertia>
        <ixx><%= J2 %></ixx>
        <ixy>0</ixy>
        <ixz>0</ixz>
        <iyy><%= J2  %></iyy>
        <iyz>0</iyz>
        <izz><%= 0.5*m1*R*R  %></izz>
      </inertia>
      <mass><%= m2 %></mass>
    </inertial>
      <visual name="secondpendulum_visual">
        <pose>0 0 <%= (L2/2.0) %> 0 0 0</pose>
        <geometry>
          <cylinder>
            <radius><%= R %></radius>
            <length><%= L2 %></length>
          </cylinder>
        </geometry>
        <material>
          <script>
            <uri>file://media/materials/scripts/gazebo.material</uri>
            <name>Gazebo/Red</name>
          </script>
        </material>
      </visual>
    </link>

    <joint name="secondpendulum_joint" type="revolute">
    <parent>firstpendulum_link</parent>
    <child>secondpendulum_link</child>
    <axis>
      <xyz>0 1 0</xyz>
      <dynamics>
        <damping><%= d2 %></damping>
      </dynamics>
    </axis>
    </joint>


    <plugin name="pendulum_stabilization" filename="libpendulum_stabilization.so">
    <cart_joint>cart_joint</cart_joint>
    <first_pendulum_joint>firstpendulum_joint</first_pendulum_joint>
    <second_pendulum_joint>secondpendulum_joint</second_pendulum_joint>
    </plugin>


  </model>
</sdf>
